Workbook

Sheet Segments
A1: Финансовая модель PANDAS
A5: Сегмент | B5: Кто это? | C5: Доля от новых клиентов | D5: Средний первый чек | E5: Средний monthly top-up | F5: 3-летний retention | G5: Ожидаемый средний портфель на конец 3 года | H5: Основной канал привлечения
A6: C — МАССОВЫЙ СТУДЕНТ | B6: Студенты региональных вузов, низкий доход | C6: 0.31 | D6: 5500 | E6: 2200 | F6: 0.42 | G6: =D6+E6*36 -> 84700 | H6: Онлайн курс + AI
A7: B — МОЛОДЫЕ ПРОФИ | B7: Молодые специалисты (IT, финтех, 22–30 лет) | C7: 0.33 | D7: 12000 | E7: 8000 | F7: 0.68 | G7: =D7+E7*36 -> 300000 | H7: Коллаборации + AI
A8: A — “ТОП” СТУДЕНТЫ | B8: Студенты топ-вуз (ВШЭ, МГУ и т.д.) | C8: 0.24 | D8: 18000 | E8: 9000 | F8: 0.75 | G8: =D8+E8*36 -> 342000 | H8: Оффлайн лекции
A9: X — New Rich | B9: Молодые предприниматели, блогеры, криптаны | C9: 0.1 | D9: 215000 | E9: 70000 | F9: 0.55 | G9: =D9+E9*36 -> 2735000 | H9: Коллаборации + AI
A10: D - Нецелевой сегмент | B10: Люди среднего возраста (30-35 лет) с плохой кредитной историей | C10: 0.02 | D10: 2000 | E10: 1000 | F10: 0.02 | G10: =D10+E10*36 -> 38000 | H10: AI

Sheet Assumptions
A1: Финансовая модель PANDAS
B5: Макроэкономические показатели
B7: Рост ВВП (прогноз) | E7: 0.012
B8: ИПЦ | E8: 0.059
B9: Ключевая ставка | E9: 0.155
J12: Целевые показатели
B15: Параметры рынка и финансовой модели
J16: Параметр | M16: Значение
B17: Название | E17: Значение | J17: Целевая доля молодёжи (до 35 лет) к концу периода | M17: 0.1
B18: Горизонт планирования | E18: 3 года | J18: Общее количество новых молодых пайщиков за 3 года (сверх основных) | M18: =N67 -> 26245
B19: Год старта | E19: 2027 год | J19: Средний портфель молодёжи на конец 3 года (те кто вошли в начале) | M19: =Segments!C6*Segments!G6+Segments!C7*Segments!G7+Segments!C8*Segments!G8+Segments!C9*Segments!G9+Segments!C10*Segments!G10 -> 481597
B20: Вознаграждение УК за управление | E20: 0.01 | J20: Общее количество пайщиков компании к концу периода | M20: 500000
B21: Премия за риск | E21: 0.03
B22: Ставка дисконтирования | E22: =E9+E21 -> 0.185
B23: Рост активов | E23: 0.08
B24: 3-х годовой retention (средний) | E24: =Segments!F6*Segments!C6+Segments!F7*Segments!C7+Segments!F8*Segments!C8+Segments!F9*Segments!C9 -> 0.5896
D27: OPEX | J27: Маркетинговые затраты | N27: CAPEX
D29: Название | E29: Стоимость | J29: Название | L29: Стоимость | N29: Название | O29: Стоимость (тыс. руб) | P29: Срок службы
D30: Посещение топ-ВУЗов (лекции и ивенты) | E30: 9000 | J30: Welcome bonus для прошедших онлайн-курс | L30: =N67/E24 -> 44513.229 | N30: Разработка AI-агента | O30: =7000 -> 7000 | P30: 10 лет
D31: Аналитика и тестирование | E31: 3000 | J31: Коллаборации с компаниями-партнерами (S7, WB, Ozon и др.) | L31: 14000 | N31: Создание онлайн-курса | O31: =4000 -> 4000 | P31: 5 лет
D32: Административная поддержка онлайн-курса | E32: 5000 | J32: Итог | L32: =SUM(L30:L31) -> 58513.229 | N32: Создание нового интерфейса в Сбере (реал тайм доходность и тд) | O32: =4000 -> 4000 | P32: 5 лет
D33: Итог | E33: =SUM(E30:E32) -> 17000 | N33: Итог | O33: =SUM(O30:O32) -> 15000
J44: Каналы продвижения
J47: Канал 1: Онлайн-курс + ВУЗы | M47: Не топ-вузы охват | N47: 48250
M48: Охват оффлайн-мероприятий за 3 года | N48: 17000
M49: Регистрация на онлайн-курс (сразу после лекции, без учета не топ вузов) | N49: 0.25 | Q49: Конверсия на этапах
M50: Регистрация на онлайн-курс рандомышей | N50: 0.46
M51: Completion курса (прошли все модули) | N51: 0.75
M52: Pass rate экзамена | N52: 0.95
M53: Активация бонуса (внесли 4000 ₽) | N53: 0.4633
M54: Остались | N54: 0.3843
J55: Канал 2: AI-агент | M55: Итого молодежи | N55: =ROUNDDOWN(N48*N49*N52*N51*N53+N47*N51*N52*N53*N50*N54,0) -> 4218
M56: Охват молодых пользователей 18–35 лет | N56: 4500000 | Q56: Конверсия на этапах
M57: Открыл и внимательно прочитал пуш-уведомление | N57: 0.07
M58: Перешёл по пушу в раздел ЗПИФ / мини-лендинг | N58: 0.33
M59: Посмотрел персональный расчёт упущенной выгоды и бонуса 1000 ₽(за онлайн-курс) | N59: 0.75
M60: Сделал первую покупку ЗПИФа | N60: 0.31
J61: Канал 3: коллаборации с партнерами | M61: Итого молодежи | N61: =ROUNDDOWN(N56*N57*N58*N59*N60,0) -> 24168
M62: Охват аудитории партнёров | N62: 4000000 | Q62: Конверсия на этапах
M63: Получил предложение кешбэка в ЗПИФ | N63: 0.42
...

Sheet AUM Build-up
A1: Финансовая модель PANDAS
A6: Квартал | B6: Всего новых (с учетом оттока) | C6: Новые A (с учетом оттока) | D6: Новые B (с учетом оттока) | E6: Новые C (с учетом оттока) | F6: Новые D (с учетом оттока) | G6: Новые X (с учетом оттока) | H6: Total Top-up всего (тыс. руб) | I6: Quarterly Top-up | J6: Beg AUM | K6: Inv. Return | L6: Mngm fee | M6: Ending AUM
A7: Q1 2027 | B7: =SUM(C7:G7) -> 1525 | C7: 380 | D7: 480 | E7: 520 | F7: 25 | G7: 120 | H7: =(C7*(Segments!$E$8*3+Segments!$D$8)+D7*(Segments!$E$7*3+Segments!$D$7) + E7*(Segments!$D$6+Segments!$E$6*3)+F7*(Segments!$D$10+Segments!$E$10*3) + G7*(Segments!$D$9+Segments!$E$9*3))/1000 -> 91797 | I7: =H7 -> 91797 | J7: 0 | K7: =(J7+I7/2)*0.08/4 -> 917.97 | L7: =(J7+I7/2)*0.01/4 -> 114.74625 | M7: =I7+J7+K7-L7 -> 92600.224
A8: Q2 2027 | B8: =SUM(C8:G8) -> 3367 | C8: =460+C7 -> 840 | D8: =590+D7 -> 1070 | E8: =610+E7 -> 1130 | F8: =32+F7 -> 57 | G8: =150+G7 -> 270 | H8: =((C8*Segments!$E$8*3+D8*Segments!$E$7*3+E8*3*Segments!$E$6+F8*Segments!$E$10*3+G8*3*Segments!$E$9) + (C8-C7)*Segments!$D$8 + (D8-D7)*Segments!$D$7 + (E8-E7)*Segments!$D$6 + (F8-F7)*Segments!$D$10 + (G8-G7)*Segments!$D$9)/1000 + H7 -> 255515 | I8: =H8-H7 -> 163718 | J8: =M7 -> 92600.224 | K8: =(J8+I8/2)*0.08/4 -> 3489.1845 | L8: =(J8+I8/2)*0.01/4 -> 436.14806 | M8: =I8+J8+K8-L8 -> 259371.26
A9: Q3 2027 | B9: =SUM(C9:G9) -> 5375 | C9: =350+C8 -> 1190 | D9: =710+D8 -> 1780 | E9: =720+E8 -> 1850 | F9: =38+F8 -> 95 | G9: =190+G8 -> 460 | H9: =((C9*Segments!$E$8*3+D9*Segments!$E$7*3+E9*3*Segments!$E$6+F9*Segments!$E$10*3+G9*3*Segments!$E$9) + (C9-C8)*Segments!$D$8 + (D9-D8)*Segments!$D$7 + (E9-E8)*Segments!$D$6 + (F9-F8)*Segments!$D$10 + (G9-G8)*Segments!$D$9)/1000 +H8 -> 499166 | I9: =H9-H8 -> 243651 | J9: =M8 -> 259371.26 | K9: =(J9+I9/2)*0.08/4 -> 7623.9352 | L9: =(J9+I9/2)*0.01/4 -> 952.9919 | M9: =I9+J9+K9-L9 -> 509693.2
A10: Q4 2027 | B10: =SUM(C10:G10) -> 7810 | C10: =530+C9 -> 1720 | D10: =820+D9 -> 2600 | E10: =810+E9 -> 2660 | F10: =45+F9 -> 140 | G10: =230+G9 -> 690 | H10: =((C10*Segments!$E$8*3+D10*Segments!$E$7*3+E10*3*Segments!$E$6+F10*Segments!$E$10*3+G10*3*Segments!$E$9) + (C10-C9)*Segments!$D$8 + (D10-D9)*Segments!$D$7 + (E10-E9)*Segments!$D$6 + (F10-F9)*Segments!$D$10 + (G10-G9)*Segments!$D$9)/1000 +H9 -> 844257 | I10: =H10-H9 -> 345091 | J10: =M9 -> 509693.2 | K10: =(J10+I10/2)*0.08/4 -> 13644.774 | L10: =(J10+I10/2)*0.01/4 -> 1705.5968 | M10: =I10+J10+K10-L10 -> 866723.38
A11: Q1 2028 | B11: =SUM(C11:G11) -> 10712 | C11: =700+C10 -> 2420 | D11: =910+D10 -> 3510 | E11: =880+E10 -> 3540 | F11: =52+F10 -> 192 | G11: =360+G10 -> 1050 | H11: =((C11*Segments!$E$8*3+D11*Segments!$E$7*3+E11*3*Segments!$E$6+F11*Segments!$E$10*3+G11*3*Segments!$E$9) + (C11-C10)*Segments!$D$8 + (D11-D10)*Segments!$D$7 + (E11-E10)*Segments!$D$6 + (F11-F10)*Segments!$D$10 + (G11-G10)*Segments!$D$9)/1000 + H10 -> 1344141 | I11: =H11-H10 -> 499884 | J11: =M10 -> 866723.38 | K11: =(J11+I11/2)*0.08/4 -> 22333.308 | L11: =(J11+I11/2)*0.01/4 -> 2791.6635 | M11: =I11+J11+K11-L11 -> 1386149
A12: Q2 2028 | B12: =SUM(C12:G12) -> 13565 | C12: =740+C11 -> 3160 | D12: =755+D11 -> 4265 | E12: =920+E11 -> 4460 | F12: =58+F11 -> 250 | G12: =380+G11 -> 1430 | H12: =((C12*Segments!$E$8*3+D12*Segments!$E$7*3+E12*3*Segments!$E$6+F12*Segments!$E$10*3+G12*3*Segments!$E$9) + (C12-C11)*Segments!$D$8 + (D12-D11)*Segments!$D$7 + (E12-E11)*Segments!$D$6 + (F12-F11)*Segments!$D$10 + (G12-G11)*Segments!$D$9)/1000 +H11 -> 1971563 | I12: =H12-H11 -> 627422 | J12: =M11 -> 1386149 | K12: =(J12+I12/2)*0.08/4 -> 33997.2 | L12: =(J12+I12/2)*0.01/4 -> 4249.6501 | M12: =I12+J12+K12-L12 -> 2043318.6
A13: Q3 2028 | B13: =SUM(C13:G13) -> 16158 | C13: =710+C12 -> 3870 | D13: =820+D12 -> 5085 | E13: =738+E12 -> 5198 | F13: =55+F12 -> 305 | G13: =270+G12 -> 1700 | H13: =285509300/1000 +H12 -> 2257072.3 | I13: =H13-H12 -> 285509.3 | J13: =M12 -> 2043318.6 | K13: =(J13+I13/2)*0.08/4 -> 43721.465 | L13: =(J13+I13/2)*0.01/4 -> 5465.1831 | M13: =I13+J13+K13-L13 -> 2367084.2
A14: Q4 2028 | B14: =SUM(C14:G14) -> 18802 | C14: =670+C13 -> 4540 | D14: =870+D13 -> 5955 | E14: =802+E13 -> 6000 | F14: =52+F13 -> 357 | G14: =250+G13 -> 1950 | H14: =((C14*Segments!$E$8*3+D14*Segments!$E$7*3+E14*3*Segments!$E$6+F14*Segments!$E$10*3+G14*3*Segments!$E$9) + (C14-C13)*Segments!$D$8 + (D14-D13)*Segments!$D$7 + (E14-E13)*Segments!$D$6 + (F14-F13)*Segments!$D$10 + (G14-G13)*Segments!$D$9)/1000+H13 -> 3053508.3 | I14: =H14-H13 -> 796436 | J14: =M13 -> 2367084.2 | K14: =(J14+I14/2)*0.08/4 -> 55306.043 | L14: =(J14+I14/2)*0.01/4 -> 6913.2554 | M14: =I14+J14+K14-L14 -> 3211912.9
A15: Q1 2029 | B15: =SUM(C15:G15) -> 21120 | C15: =590+C14 -> 5130 | D15: =780+D14 -> 6735 | E15: =680+E14 -> 6680 | F15: =48+F14 -> 405 | G15: =220+G14 -> 2170 | H15: =((C15*Segments!$E$8*3+D15*Segments!$E$7*3+E15*3*Segments!$E$6+F15*Segments!$E$10*3+G15*3*Segments!$E$9) + (C15-C14)*Segments!$D$8 + (D15-D14)*Segments!$D$7 + (E15-E14)*Segments!$D$6 + (F15-F14)*Segments!$D$10 + (G15-G14)*Segments!$D$9)/1000 +H14 -> 3925777.3 | I15: =H15-H14 -> 872269 | J15: =M14 -> 3211912.9 | K15: =(J15+I15/2)*0.08/4 -> 72960.949 | L15: =(J15+I15/2)*0.01/4 -> 9120.1186 | M15: =I15+J15+K15-L15 -> 4148022.8
A16: Q2 2029 | B16: =SUM(C16:G16) -> 23142 | C16: =520+C15 -> 5650 | D16: =690+D15 -> 7425 | E16: =580+E15 -> 7260 | F16: =42+F15 -> 447 | G16: =190+G15 -> 2360 | H16: =((C16*Segments!$E$8*3+D16*Segments!$E$7*3+E16*3*Segments!$E$6+F16*Segments!$E$10*3+G16*3*Segments!$E$9) + (C16-C15)*Segments!$D$8 + (D16-D15)*Segments!$D$7 + (E16-E15)*Segments!$D$6 + (F16-F15)*Segments!$D$10 + (G16-G15)*Segments!$D$9)/1000 +H15 -> 4863148.3 | I16: =H16-H15 -> 937371 | J16: =M15 -> 4148022.8 | K16: =(J16+I16/2)*0.08/4 -> 92334.165 | L16: =(J16+I16/2)*0.01/4 -> 11541.771 | M16: =I16+J16+K16-L16 -> 5166186.2
A17: Q3 2029 | B17: =SUM(C17:G17) -> 24657 | C17: =250+C16 -> 5900 | D17: =590+D16 -> 8015 | E17: =480+E16 -> 7740 | F17: =35+F16 -> 482 | G17: =160+G16 -> 2520 | H17: =((C17*Segments!$E$8*3+D17*Segments!$E$7*3+E17*3*Segments!$E$6+F17*Segments!$E$10*3+G17*3*Segments!$E$9) + (C17-C16)*Segments!$D$8 + (D17-D16)*Segments!$D$7 + (E17-E16)*Segments!$D$6 + (F17-F16)*Segments!$D$10 + (G17-G16)*Segments!$D$9)/1000 +H16 -> 5845228.3 | I17: =H17-H16 -> 982080 | J17: =M16 -> 5166186.2 | K17: =(J17+I17/2)*0.08/4 -> 113144.52 | L17: =(J17+I17/2)*0.01/4 -> 14143.065 | M17: =I17+J17+K17-L17 -> 6247267.6
A18: Q4 2029 | B18: =SUM(C18:G18) -> 26245 | C18: =444+C17 -> 6344 | D18: =532+D17 -> 8547 | E18: =392+E17 -> 8132 | F18: =55+F17 -> 537 | G18: =165+G17 -> 2685 | H18: =((C18*Segments!$E$8*3+D18*Segments!$E$7*3+E18*3*Segments!$E$6+F18*Segments!$E$10*3+G18*3*Segments!$E$9) + (C18-C17)*Segments!$D$8 + (D18-D17)*Segments!$D$7 + (E18-E17)*Segments!$D$6 + (F18-F17)*Segments!$D$10 + (G18-G17)*Segments!$D$9)/1000+H17 -> 6892893.5 | I18: =H18-H17 -> 1047665.2 | J18: =M17 -> 6247267.6 | K18: =(J18+I18/2)*0.08/4 -> 135422 | L18: =(J18+I18/2)*0.01/4 -> 16927.751 | M18: =I18+J18+K18-L18 -> 7413427.1

Sheet P&L
A1: Финансовая модель PANDAS
B4: Квартал | C4: Коммисия УК за управление | D4: Вознаграждение за прибыль | E4: Итог Общая выручка | F4: Расходы на прямой маркетинг | G4: Адм. расходы | H4: Итог OPEX | I4: Амортизация | J4: EBIT | K4: Налог на прибыль | L4: Net Profit
B5: Q1 2027 | C5: {='AUM Build-up'!L7:L18} -> 114.74625 | D5: =MAX(0,('AUM Build-up'!K7-'AUM Build-up'!L7)*0.05) -> 40.161188 | E5: =C5+D5 -> 154.90744 | F5: =Assumptions!$L$32/36 -> 1625.3675 | G5: =Assumptions!$E$33/36 -> 472.22222 | H5: =F5+G5 -> 2097.5897 | I5: =Assumptions!$O$30/360+Assumptions!$O$31/180+Assumptions!$O$32/180 -> 63.888889 | J5: =E5-H5-I5 -> -2006.5712 | K5: =MAX(0,J5*0.2) -> 0 | L5: =J5-K5 -> -2006.5712
B6: Q2 2027 | C6: 436.14806 | D6: =MAX(0,('AUM Build-up'!K8-'AUM Build-up'!L8)*0.05) -> 152.65182 | E6: =C6+D6 -> 588.79988 | F6: =Assumptions!$L$32/36 -> 1625.3675 | G6: =Assumptions!$E$33/36 -> 472.22222 | H6: =F6+G6 -> 2097.5897 | I6: =Assumptions!$O$30/360+Assumptions!$O$31/180+Assumptions!$O$32/180 -> 63.888889 | J6: =E6-H6-I6 -> -1572.6787 | K6: =MAX(0,J6*0.2) -> 0 | L6: =J6-K6 -> -1572.6787
B7: Q3 2027 | C7: 952.9919 | D7: =MAX(0,('AUM Build-up'!K9-'AUM Build-up'!L9)*0.05) -> 333.54717 | E7: =C7+D7 -> 1286.5391 | F7: =Assumptions!$L$32/36 -> 1625.3675 | G7: =Assumptions!$E$33/36 -> 472.22222 | H7: =F7+G7 -> 2097.5897 | I7: =Assumptions!$O$30/360+Assumptions!$O$31/180+Assumptions!$O$32/180 -> 63.888889 | J7: =E7-H7-I7 -> -874.93953 | K7: =MAX(0,J7*0.2) -> 0 | L7: =J7-K7 -> -874.93953
B8: Q4 2027 | C8: 1705.5968 | D8: =MAX(0,('AUM Build-up'!K10-'AUM Build-up'!L10)*0.05) -> 596.95887 | E8: =C8+D8 -> 2302.5556 | F8: =Assumptions!$L$32/36 -> 1625.3675 | G8: =Assumptions!$E$33/36 -> 472.22222 | H8: =F8+G8 -> 2097.5897 | I8: =Assumptions!$O$30/360+Assumptions!$O$31/180+Assumptions!$O$32/180 -> 63.888889 | J8: =E8-H8-I8 -> 141.07703 | K8: =MAX(0,J8*0.2) -> 28.215406 | L8: =J8-K8 -> 112.86163
B9: Q1 2028 | C9: 2791.6635 | D9: =MAX(0,('AUM Build-up'!K11-'AUM Build-up'!L11)*0.05) -> 977.08221 | E9: =C9+D9 -> 3768.7457 | F9: =Assumptions!$L$32/36*1.06 -> 1722.8895 | G9: =Assumptions!$E$33/36*1.06 -> 500.55556 | H9: =F9+G9 -> 2223.4451 | I9: =Assumptions!$O$30/360+Assumptions!$O$31/180+Assumptions!$O$32/180 -> 63.888889 | J9: =E9-H9-I9 -> 1481.4117 | K9: =MAX(0,J9*0.2) -> 296.28234 | L9: =J9-K9 -> 1185.1293
B10: Q2 2028 | C10: 4249.6501 | D10: =MAX(0,('AUM Build-up'!K12-'AUM Build-up'!L12)*0.05) -> 1487.3775 | E10: =C10+D10 -> 5737.0276 | F10: =Assumptions!$L$32/36*1.06 -> 1722.8895 | G10: =Assumptions!$E$33/36*1.06 -> 500.55556 | H10: =F10+G10 -> 2223.4451 | I10: =Assumptions!$O$30/360+Assumptions!$O$31/180+Assumptions!$O$32/180 -> 63.888889 | J10: =E10-H10-I10 -> 3449.6936 | K10: =MAX(0,J10*0.2) -> 689.93872 | L10: =J10-K10 -> 2759.7549
B11: Q3 2028 | C11: 5465.1831 | D11: =MAX(0,('AUM Build-up'!K13-'AUM Build-up'!L13)*0.05) -> 1912.8141 | E11: =C11+D11 -> 7377.9971 | F11: =Assumptions!$L$32/36*1.06 -> 1722.8895 | G11: =Assumptions!$E$33/36*1.06 -> 500.55556 | H11: =F11+G11 -> 2223.4451 | I11: =Assumptions!$O$30/360+Assumptions!$O$31/180+Assumptions!$O$32/180 -> 63.888889 | J11: =E11-H11-I11 -> 5090.6632 | K11: =MAX(0,J11*0.2) -> 1018.1326 | L11: =J11-K11 -> 4072.5305
B12: Q4 2028 | C12: 6913.2554 | D12: =MAX(0,('AUM Build-up'!K14-'AUM Build-up'!L14)*0.05) -> 2419.6394 | E12: =C12+D12 -> 9332.8948 | F12: =Assumptions!$L$32/36*1.06 -> 1722.8895 | G12: =Assumptions!$E$33/36*1.06 -> 500.55556 | H12: =F12+G12 -> 2223.4451 | I12: =Assumptions!$O$30/360+Assumptions!$O$31/180+Assumptions!$O$32/180 -> 63.888889 | J12: =E12-H12-I12 -> 7045.5608 | K12: =MAX(0,J12*0.2) -> 1409.1122 | L12: =J12-K12 -> 5636.4486
B13: Q1 2029 | C13: 9120.1186 | D13: =MAX(0,('AUM Build-up'!K15-'AUM Build-up'!L15)*0.05) -> 3192.0415 | E13: =C13+D13 -> 12312.16 | F13: =Assumptions!$L$32/36*1.06*1.06 -> 1826.2629 | G13: =Assumptions!$E$33/36*1.06*1.06 -> 530.58889 | H13: =F13+G13 -> 2356.8518 | I13: =Assumptions!$O$30/360+Assumptions!$O$31/180+Assumptions!$O$32/180 -> 63.888889 | J13: =E13-H13-I13 -> 9891.4194 | K13: =MAX(0,J13*0.2) -> 1978.2839 | L13: =J13-K13 -> 7913.1356
B14: Q2 2029 | C14: 11541.771 | D14: =MAX(0,('AUM Build-up'!K16-'AUM Build-up'!L16)*0.05) -> 4039.6197 | E14: =C14+D14 -> 15581.39 | F14: =Assumptions!$L$32/36*1.06*1.06 -> 1826.2629 | G14: =Assumptions!$E$33/36*1.06*1.06 -> 530.58889 | H14: =F14+G14 -> 2356.8518 | I14: =Assumptions!$O$30/360+Assumptions!$O$31/180+Assumptions!$O$32/180 -> 63.888889 | J14: =E14-H14-I14 -> 13160.65 | K14: =MAX(0,J14*0.2) -> 2632.1299 | L14: =J14-K14 -> 10528.52
B15: Q3 2029 | C15: 14143.065 | D15: =MAX(0,('AUM Build-up'!K17-'AUM Build-up'!L17)*0.05) -> 4950.0729 | E15: =C15+D15 -> 19093.138 | F15: =Assumptions!$L$32/36*1.06*1.06 -> 1826.2629 | G15: =Assumptions!$E$33/36*1.06*1.06 -> 530.58889 | H15: =F15+G15 -> 2356.8518 | I15: =Assumptions!$O$30/360+Assumptions!$O$31/180+Assumptions!$O$32/180 -> 63.888889 | J15: =E15-H15-I15 -> 16672.398 | K15: =MAX(0,J15*0.2) -> 3334.4795 | L15: =J15-K15 -> 13337.918
B16: Q4 2029 | C16: 16927.751 | D16: =MAX(0,('AUM Build-up'!K18-'AUM Build-up'!L18)*0.05) -> 5924.7127 | E16: =C16+D16 -> 22852.463 | F16: =Assumptions!$L$32/36*1.06*1.06 -> 1826.2629 | G16: =Assumptions!$E$33/36*1.06*1.06 -> 530.58889 | H16: =F16+G16 -> 2356.8518 | I16: =Assumptions!$O$30/360+Assumptions!$O$31/180+Assumptions!$O$32/180 -> 63.888889 | J16: =E16-H16-I16 -> 20431.723 | K16: =MAX(0,J16*0.2) -> 4086.3445 | L16: =J16-K16 -> 16345.378

Sheet DCF
A1: Финансовая модель PANDAS
B4: Квартал | C4: Амортизация | D4: Net Profit | E4: CAPEX | F4: FCF | G4: Compound Rate | H4: DCF
B5: Q1 2027 | C5: ='P&L'!I5 -> 63.888889 | D5: ='P&L'!L5 -> -2006.5712 | E5: =Assumptions!$O$30/2 -> 3500 | F5: =D5+C5-E5 -> -5442.6823 | G5: =($L$9+1)^(ROW()-5) -> 1 | H5: =F5/G5 -> -5442.6823
B6: Q2 2027 | C6: ='P&L'!I6 -> 63.888889 | D6: ='P&L'!L6 -> -1572.6787 | E6: =Assumptions!$O$30/2 + Assumptions!O31 -> 7500 | F6: =D6+C6-E6 -> -9008.7898 | G6: =($L$9+1)^(ROW()-5) -> 1.043349 | H6: =F6/G6 -> -8634.4935
B7: Q3 2027 | C7: ='P&L'!I7 -> 63.888889 | D7: ='P&L'!L7 -> -874.93953 | E7: 0 | F7: =D7+C7-E7 -> -811.05064 | G7: =($L$9+1)^(ROW()-5) -> 1.0885771 | H7: =F7/G7 -> -745.05579
B8: Q4 2027 | C8: ='P&L'!I8 -> 63.888889 | D8: ='P&L'!L8 -> 112.86163 | E8: =Assumptions!O32 -> 4000 | F8: =D8+C8-E8 -> -3823.2495 | G8: =($L$9+1)^(ROW()-5) -> 1.1357657 | H8: =F8/G8 -> -3366.2307 | K8: WACC | L8: =Assumptions!E22 -> 0.185
B9: Q1 2028 | C9: ='P&L'!I9 -> 63.888889 | D9: ='P&L'!L9 -> 1185.1293 | E9: 0 | F9: =D9+C9-E9 -> 1249.0182 | G9: =($L$9+1)^(ROW()-5) -> 1.185 | H9: =F9/G9 -> 1054.0238 | K9: Q % | L9: =POWER(1+L8,0.25)-1 -> 0.04334896
B10: Q2 2028 | C10: ='P&L'!I10 -> 63.888889 | D10: ='P&L'!L10 -> 2759.7549 | E10: 0 | F10: =D10+C10-E10 -> 2823.6438 | G10: =($L$9+1)^(ROW()-5) -> 1.2363685 | H10: =F10/G10 -> 2283.8205 | K10: NPV (тыс. руб) | L10: =SUM(H5:H16) -> 24558.065
B11: Q3 2028 | C11: ='P&L'!I11 -> 63.888889 | D11: ='P&L'!L11 -> 4072.5305 | E11: 0 | F11: =D11+C11-E11 -> 4136.4194 | G11: =($L$9+1)^(ROW()-5) -> 1.2899638 | H11: =F11/G11 -> 3206.6166 | K11: IRR | L11: =IRR(J21:L21) -> 0.65477088
B12: Q4 2028 | C12: ='P&L'!I12 -> 63.888889 | D12: ='P&L'!L12 -> 5636.4486 | E12: 0 | F12: =D12+C12-E12 -> 5700.3375 | G12: =($L$9+1)^(ROW()-5) -> 1.3458824 | H12: =F12/G12 -> 4235.3905
B13: Q1 2029 | C13: ='P&L'!I13 -> 63.888889 | D13: ='P&L'!L13 -> 7913.1356 | E13: 0 | F13: =D13+C13-E13 -> 7977.0244 | G13: =($L$9+1)^(ROW()-5) -> 1.404225 | H13: =F13/G13 -> 5680.731
B14: Q2 2029 | C14: ='P&L'!I14 -> 63.888889 | D14: ='P&L'!L14 -> 10528.52 | E14: 0 | F14: =D14+C14-E14 -> 10592.409 | G14: =($L$9+1)^(ROW()-5) -> 1.4650967 | H14: =F14/G14 -> 7229.8359
B15: Q3 2029 | C15: ='P&L'!I15 -> 63.888889 | D15: ='P&L'!L15 -> 13337.918 | E15: 0 | F15: =D15+C15-E15 -> 13401.807 | G15: =($L$9+1)^(ROW()-5) -> 1.5286071 | H15: =F15/G15 -> 8767.3326
B16: Q4 2029 | C16: ='P&L'!I16 -> 63.888889 | D16: ='P&L'!L16 -> 16345.378 | E16: 0 | F16: =D16+C16-E16 -> 16409.267 | G16: =($L$9+1)^(ROW()-5) -> 1.5948706 | H16: =F16/G16 -> 10288.776
J19: Агрегированные свободные денежные потоки
J20: 2027 | K20: 2028 | L20: 2029
J21: =SUM(H5:H8) -> -18188.462 | K21: =SUM(H9:H12) -> 10779.851 | L21: =SUM(H13:H16) -> 31966.676

Sheet Метрики
A1: Финансовая модель PANDAS
C7: Метрика | D7: 2027 | E7: 2028 | F7: 2029 | G7: Итого / Среднее
C8: Gross Margin | D8: =SUM('P&L'!J5:J8)/SUM('P&L'!E5:E8) -> -0.99545568 | E8: =SUM('P&L'!J9:J12)/SUM('P&L'!E9:E12) -> 0.65101069 | F8: =SUM('P&L'!J13:J16)/SUM('P&L'!E13:E16) -> 0.86135338 | G8: =SUM('P&L'!J5:J16)/SUM('P&L'!E5:E16) -> 0.72628159
C9: CAC (руб) | D9: - | E9: - | F9: - | G9: =(1000+Assumptions!E32+Assumptions!O31+Assumptions!O30+Assumptions!E30+Assumptions!L31)/26245 * 1000 -> 1524.0998
C10: LTV | D10: - | E10: - | F10: - | G10: =SUM('P&L'!L5:L16)/Assumptions!N67 * 1000 * (1/(1-(Segments!F6*Segments!C6+Segments!F7*Segments!C7+Segments!F8*Segments!C8+Segments!F9*Segments!C9+Segments!F10*Segments!C10))) -> 5337.8332
C11: LTV / CAC | D11: - | E11: - | F11: - | G11: =G10/G9 -> 3.5022858
C12: DPP | D12: - | E12: - | F12: - | G12: 25 мес.
C13: ROI | D13: - | E13: - | F13: - | G13: =G8 -> 0.72628159
C14: IRR | D14: - | E14: - | F14: - | G14: =DCF!L11 -> 0.65477088
C15: NPV | D15: - | E15: - | F15: - | G15: =DCF!L10 * 1000 -> 24558065
C16: Доля молодёжи в новых клиентах | D16: 0.06 | E16: 0.08 | F16: 0.11 | G16: 0.11

Sheet Sensivity Analysis
A1: Финансовая модель PANDAS
C5: Параметр | E5: NPV base | F5: NPV pos | G5: NPV neg | H5: Изменение
C6: Средний monthly top-up | E6: =DCF!$L$10 -> 24558.065 | F6: 28975 | G6: 20136.33 | H6: 10%+-
C7: OPEX + CAPEX + MARKETING | E7: =DCF!$L$10 -> 24558.065 | F7: 27790.3 | G7: 21312.61 | H7: 10%-+
C8: Количество новых клиентов | E8: =DCF!$L$10 -> 24558.065 | F8: 29941.3 | G8: 19159.13 | H8: 10%+-
C9: WACC | E9: =DCF!$L$10 -> 24558.065 | F9: 26103.01 | G9: 23099.49 | H9: 2п.п. -+
C10: Средний первый чек | E10: =DCF!$L$10 -> 24558.065 | F10: 25523.83 | G10: 23592.3 | H10: 10%+-
J11: Изменение NPV
J12: =G10-E10 -> -965.76485 | K12: =F10-E10 -> 965.76515
J13: =G9-E9 -> -1458.5749 | K13: =F9-E9 -> 1544.9451
J14: =G7-E7 -> -3245.4549 | K14: =F7-E7 -> 3232.2351
J15: =G6-E6 -> -4421.7349 | K15: =F6-E6 -> 4416.9351
J16: =G8-E8 -> -5398.9349 | K16: =F8-E8 -> 5383.2351
